Workbook

Sheet Objectifs
A1: R001 | B1: ="Non RO - "&VLOOKUP(A1,'Paramétrage'!$E$6:$F$16,2,FALSE) -> Non RO - LIGNE 1 | C1: 45292 | D1: 45323 | E1: 45352 | F1: 45383 | G1: 45413 | H1: 45444 | I1: 45474 | J1: 45505 | K1: 45536 | L1: 45566 | M1: 45597 | N1: 45627 | O1: 45658 | P1: 45689 | Q1: 45717 | R1: 45748 | S1: 45778 | T1: 45809 | U1: 45839 | V1: 45870 | W1: 45901 | X1: 45931 | Y1: 45962 | Z1: 45992
B2: ='Paramétrage'!J6 -> PRESSES | C2: 0.02 | D2: 0.02 | E2: 0.02 | F2: 0.02 | G2: 0.02 | H2: 0.02 | I2: 0.02 | J2: 0.02 | K2: 0.0175 | L2: 0.015 | M2: 0.0125 | N2: 0.01 | O2: 0.01 | P2: 0.01 | Q2: 0.01 | R2: 0.01 | S2: 0.01 | T2: 0.01 | U2: 0.01 | V2: 0.01 | W2: 0.01 | X2: 0.01 | Y2: 0.01 | Z2: 0.01
B3: ='Paramétrage'!J7 -> EQUIPEMENTS | C3: 0.08 | D3: 0.08 | E3: 0.08 | F3: 0.08 | G3: 0.08 | H3: 0.08 | I3: 0.08 | J3: 0.08 | K3: 0.06975 | L3: 0.0595 | M3: 0.04925 | N3: 0.039 | O3: 0.039 | P3: 0.039 | Q3: 0.039 | R3: 0.039 | S3: 0.039 | T3: 0.039 | U3: 0.039 | V3: 0.039 | W3: 0.039 | X3: 0.039 | Y3: 0.039 | Z3: 0.039
B4: ='Paramétrage'!J8 -> CONVOYEURS | C4: 0.002 | D4: 0.002 | E4: 0.002 | F4: 0.002 | G4: 0.002 | H4: 0.002 | I4: 0.002 | J4: 0.002 | K4: 0.00175 | L4: 0.0015 | M4: 0.00125 | N4: 0.001 | O4: 0.001 | P4: 0.001 | Q4: 0.001 | R4: 0.001 | S4: 0.001 | T4: 0.001 | U4: 0.001 | V4: 0.001 | W4: 0.001 | X4: 0.001 | Y4: 0.001 | Z4: 0.001
B5: ='Paramétrage'!J9 -> OUTILS | C5: 0.035 | D5: 0.035 | E5: 0.035 | F5: 0.035 | G5: 0.035 | H5: 0.035 | I5: 0.035 | J5: 0.035 | K5: 0.03375 | L5: 0.0325 | M5: 0.03125 | N5: 0.03 | O5: 0.03 | P5: 0.03 | Q5: 0.03 | R5: 0.03 | S5: 0.03 | T5: 0.03 | U5: 0.03 | V5: 0.03 | W5: 0.03 | X5: 0.03 | Y5: 0.03 | Z5: 0.03
B6: ='Paramétrage'!J10 -> ESSUYAGE OUTIL | C6: 0.025 | D6: 0.025 | E6: 0.025 | F6: 0.025 | G6: 0.025 | H6: 0.025 | I6: 0.025 | J6: 0.025 | K6: 0.02125 | L6: 0.0175 | M6: 0.01375 | N6: 0.01 | O6: 0.01 | P6: 0.01 | Q6: 0.01 | R6: 0.01 | S6: 0.01 | T6: 0.01 | U6: 0.01 | V6: 0.01 | W6: 0.01 | X6: 0.01 | Y6: 0.01 | Z6: 0.01
B7: ='Paramétrage'!J11 -> MECANISATIONS | C7: 0.01 | D7: 0.01 | E7: 0.01 | F7: 0.01 | G7: 0.01 | H7: 0.01 | I7: 0.01 | J7: 0.01 | K7: 0.01 | L7: 0.01 | M7: 0.01 | N7: 0.01 | O7: 0.01 | P7: 0.01 | Q7: 0.01 | R7: 0.01 | S7: 0.01 | T7: 0.01 | U7: 0.01 | V7: 0.01 | W7: 0.01 | X7: 0.01 | Y7: 0.01 | Z7: 0.01
B8: ='Paramétrage'!J12 -> MATIERE | C8: 0.005 | D8: 0.005 | E8: 0.005 | F8: 0.005 | G8: 0.005 | H8: 0.005 | I8: 0.005 | J8: 0.005 | K8: 0.00425 | L8: 0.0035 | M8: 0.00275 | N8: 0.002 | O8: 0.002 | P8: 0.002 | Q8: 0.002 | R8: 0.002 | S8: 0.002 | T8: 0.002 | U8: 0.002 | V8: 0.002 | W8: 0.002 | X8: 0.002 | Y8: 0.002 | Z8: 0.002
B9: ='Paramétrage'!J13 -> ATTENTE AMONT | C9: 0.005 | D9: 0.005 | E9: 0.005 | F9: 0.005 | G9: 0.005 | H9: 0.005 | I9: 0.005 | J9: 0.005 | K9: 0.00425 | L9: 0.0035 | M9: 0.00275 | N9: 0.002 | O9: 0.002 | P9: 0.002 | Q9: 0.002 | R9: 0.002 | S9: 0.002 | T9: 0.002 | U9: 0.002 | V9: 0.002 | W9: 0.002 | X9: 0.002 | Y9: 0.002 | Z9: 0.002
B10: ='Paramétrage'!J14 -> SATURATION | C10: 0.01 | D10: 0.01 | E10: 0.01 | F10: 0.01 | G10: 0.01 | H10: 0.01 | I10: 0.01 | J10: 0.01 | K10: 0.00875 | L10: 0.0075 | M10: 0.00625 | N10: 0.005 | O10: 0.005 | P10: 0.005 | Q10: 0.005 | R10: 0.005 | S10: 0.005 | T10: 0.005 | U10: 0.005 | V10: 0.005 | W10: 0.005 | X10: 0.005 | Y10: 0.005 | Z10: 0.005
B11: ='Paramétrage'!J15 -> PREPARATION CONVOI | C11: 0.005 | D11: 0.005 | E11: 0.005 | F11: 0.005 | G11: 0.005 | H11: 0.005 | I11: 0.005 | J11: 0.005 | K11: 0.0045 | L11: 0.004 | M11: 0.0035 | N11: 0.003 | O11: 0.003 | P11: 0.003 | Q11: 0.003 | R11: 0.003 | S11: 0.003 | T11: 0.003 | U11: 0.003 | V11: 0.003 | W11: 0.003 | X11: 0.003 | Y11: 0.003 | Z11: 0.003
B12: ='Paramétrage'!J16 -> OPERATEURS | C12: 0.005 | D12: 0.005 | E12: 0.005 | F12: 0.005 | G12: 0.005 | H12: 0.005 | I12: 0.005 | J12: 0.005 | K12: 0.00425 | L12: 0.0035 | M12: 0.00275 | N12: 0.002 | O12: 0.002 | P12: 0.002 | Q12: 0.002 | R12: 0.002 | S12: 0.002 | T12: 0.002 | U12: 0.002 | V12: 0.002 | W12: 0.002 | X12: 0.002 | Y12: 0.002 | Z12: 0.002
B13: ='Paramétrage'!J17 -> NON RENSEIGNEE | C13: 0.01 | D13: 0.01 | E13: 0.01 | F13: 0.01 | G13: 0.01 | H13: 0.01 | I13: 0.01 | J13: 0.01 | K13: 0.00775 | L13: 0.0055 | M13: 0.00325 | N13: 0.001 | O13: 0.001 | P13: 0.001 | Q13: 0.001 | R13: 0.001 | S13: 0.001 | T13: 0.001 | U13: 0.001 | V13: 0.001 | W13: 0.001 | X13: 0.001 | Y13: 0.001 | Z13: 0.001
... B24: ='Paramétrage'!J28 -> PERTES CYCLE | C24: 0.1 | D24: 0.1 | E24: 0.1 | F24: 0.1 | G24: 0.1 | H24: 0.1 | I24: 0.1 | J24: 0.1 | K24: 0.085 | L24: 0.07 | M24: 0.055 | N24: 0.04 | O24: 0.04 | P24: 0.04 | Q24: 0.04 | R24: 0.04 | S24: 0.04 | T24: 0.04 | U24: 0.04 | V24: 0.04 | W24: 0.04 | X24: 0.04 | Y24: 0.04 | Z24: 0.04
B25: NON RO GLOBAL | C25: =SUM(C2:C24) -> 0.41 | D25: =SUM(D2:D24) -> 0.41 | E25: =SUM(E2:E24) -> 0.41 | F25: =SUM(F2:F24) -> 0.41 | G25: =SUM(G2:G24) -> 0.41 | H25: =SUM(H2:H24) -> 0.41 | I25: =SUM(I2:I24) -> 0.41 | J25: =SUM(J2:J24) -> 0.41 | ... Z25: =SUM(Z2:Z24) -> 0.216
B26: ='Paramétrage'!J29 -> ARRETS MACHINES | C26: =SUM(C2:C4) -> 0.102 | D26: =SUM(D2:D4) -> 0.102 | E26: =SUM(E2:E4) -> 0.102 | F26: =SUM(F2:F4) -> 0.102 | G26: =SUM(G2:G4) -> 0.102 | H26: =SUM(H2:H4) -> 0.102 | I26: =SUM(I2:I4) -> 0.102 | J26: =SUM(J2:J4) -> 0.102 | ... Z26: =SUM(Z2:Z4) -> 0.05
B27: ='Paramétrage'!J30 -> ARRETS OUTILS | C27: =SUM(C5:C7) -> 0.07 | D27: =SUM(D5:D7) -> 0.07 | E27: =SUM(E5:E7) -> 0.07 | F27: =SUM(F5:F7) -> 0.07 | G27: =SUM(G5:G7) -> 0.07 | H27: =SUM(H5:H7) -> 0.07 | I27: =SUM(I5:I7) -> 0.07 | J27: =SUM(J5:J7) -> 0.07 | ... Z27: =SUM(Z5:Z7) -> 0.05
B28: ='Paramétrage'!J31 -> ARRETS INDUITS | C28: =SUM(C8:C13) -> 0.04 | D28: =SUM(D8:D13) -> 0.04 | E28: =SUM(E8:E13) -> 0.04 | F28: =SUM(F8:F13) -> 0.04 | G28: =SUM(G8:G13) -> 0.04 | H28: =SUM(H8:H13) -> 0.04 | I28: =SUM(I8:I13) -> 0.04 | J28: =SUM(J8:J13) -> 0.04 | ... Z28: =SUM(Z8:Z13) -> 0.015
B29: ='Paramétrage'!J32 -> ARRETS FONCTIONNELS | C29: =SUM(C14:C21) -> 0.093 | D29: =SUM(D14:D21) -> 0.093 | E29: =SUM(E14:E21) -> 0.093 | F29: =SUM(F14:F21) -> 0.093 | G29: =SUM(G14:G21) -> 0.093 | H29: =SUM(H14:H21) -> 0.093 | I29: =SUM(I14:I21) -> 0.093 | J29: =SUM(J14:J21) -> 0.093 | ... Z29: =SUM(Z14:Z21) -> 0.056
B30: ='Paramétrage'!J33 -> PERTES QUALITE | C30: =SUM(C22:C23) -> 0.005 | D30: =SUM(D22:D23) -> 0.005 | E30: =SUM(E22:E23) -> 0.005 | F30: =SUM(F22:F23) -> 0.005 | G30: =SUM(G22:G23) -> 0.005 | H30: =SUM(H22:H23) -> 0.005 | I30: =SUM(I22:I23) -> 0.005 | J30: =SUM(J22:J23) -> 0.005 | ... Z30: =SUM(Z22:Z23) -> 0.005
B31: ='Paramétrage'!J34 -> PERTES CYCLE | C31: =C24 -> 0.1 | D31: =D24 -> 0.1 | E31: =E24 -> 0.1 | F31: =F24 -> 0.1 | G31: =G24 -> 0.1 | H31: =H24 -> 0.1 | I31: =I24 -> 0.1 | J31: =J24 -> 0.1 | ... Z31: =Z24 -> 0.04
B32: RO GLOBAL | C32: =100%-C25 -> 0.59 | D32: =100%-D25 -> 0.59 | E32: =100%-E25 -> 0.59 | F32: =100%-F25 -> 0.59 | G32: =100%-G25 -> 0.59 | H32: =100%-H25 -> 0.59 | I32: =100%-I25 -> 0.59 | J32: =100%-J25 -> 0.59 | ... Z32: =100%-Z25 -> 0.784
A34: R803 | B34: ="Non RO - "&VLOOKUP(A34,'Paramétrage'!$E$6:$F$16,2,FALSE) -> Non RO - L803 | C34: =C1 -> 45292 | D34: =D1 -> 45323 | E34: =E1 -> 45352 | F34: =F1 -> 45383 | G34: =G1 -> 45413 | H34: =H1 -> 45444 | I34: =I1 -> 45474 | J34: =J1 -> 45505 | ... Z34: =Z1 -> 45992
B35: =B2 -> PRESSES | C35: 0.033 | D35: 0.033 | E35: 0.033 | F35: 0.033 | G35: 0.033 | H35: 0.033 | I35: 0.033 | J35: 0.033 | K35: 0.033 | L35: 0.033 | M35: 0.033 | N35: 0.033 | O35: =N35 -> 0.033 | P35: =O35 -> 0.033 | Q35: =P35 -> 0.033 | R35: =Q35 -> 0.033 | S35: =R35 -> 0.033 | T35: =S35 -> 0.033 | U35: =T35 -> 0.033 | V35: =U35 -> 0.033 | ... Z35: =Y35 -> 0.033
B36: =B3 -> EQUIPEMENTS | C36: 0.029 | D36: 0.029 | E36: 0.029 | F36: 0.029 | G36: 0.029 | H36: 0.029 | I36: 0.029 | J36: 0.029 | K36: 0.029 | L36: 0.029 | M36: 0.029 | N36: 0.029 | O36: =N36 -> 0.029 | P36: =O36 -> 0.029 | Q36: =P36 -> 0.029 | R36: =Q36 -> 0.029 | S36: =R36 -> 0.029 | T36: =S36 -> 0.029 | U36: =T36 -> 0.029 | V36: =U36 -> 0.029 | ... Z36: =Y36 -> 0.029
B37: =B4 -> CONVOYEURS | C37: 0.001 | D37: 0.001 | E37: 0.001 | F37: 0.001 | G37: 0.001 | H37: 0.001 | I37: 0.001 | J37: 0.001 | K37: 0.001 | L37: 0.001 | M37: 0.001 | N37: 0.001 | O37: =N37 -> 0.001 | P37: =O37 -> 0.001 | Q37: =P37 -> 0.001 | R37: =Q37 -> 0.001 | S37: =R37 -> 0.001 | T37: =S37 -> 0.001 | U37: =T37 -> 0.001 | V37: =U37 -> 0.001 | ... Z37: =Y37 -> 0.001
B38: =B5 -> OUTILS | C38: 0.013 | D38: 0.013 | E38: 0.013 | F38: 0.013 | G38: 0.013 | H38: 0.013 | I38: 0.013 | J38: 0.013 | K38: 0.013 | L38: 0.013 | M38: 0.013 | N38: 0.013 | O38: =N38 -> 0.013 | P38: =O38 -> 0.013 | Q38: =P38 -> 0.013 | R38: =Q38 -> 0.013 | S38: =R38 -> 0.013 | T38: =S38 -> 0.013 | U38: =T38 -> 0.013 | V38: =U38 -> 0.013 | ... Z38: =Y38 -> 0.013
B39: =B6 -> ESSUYAGE OUTIL | C39: 0.004 | D39: 0.004 | E39: 0.004 | F39: 0.004 | G39: 0.004 | H39: 0.004 | I39: 0.004 | J39: 0.004 | K39: 0.004 | L39: 0.004 | M39: 0.004 | N39: 0.004 | O39: =N39 -> 0.004 | P39: =O39 -> 0.004 | Q39: =P39 -> 0.004 | R39: =Q39 -> 0.004 | S39: =R39 -> 0.004 | T39: =S39 -> 0.004 | U39: =T39 -> 0.004 | V39: =U39 -> 0.004 | ... Z39: =Y39 -> 0.004
B40: =B7 -> MECANISATIONS | C40: 0.0208 | D40: 0.0208 | E40: 0.0208 | F40: 0.0208 | G40: 0.0208 | H40: 0.0208 | I40: 0.0208 | J40: 0.0208 | K40: 0.0208 | L40: 0.0208 | M40: 0.0208 | N40: 0.0208 | O40: =N40 -> 0.0208 | P40: =O40 -> 0.0208 | Q40: =P40 -> 0.0208 | R40: =Q40 -> 0.0208 | S40: =R40 -> 0.0208 | T40: =S40 -> 0.0208 | U40: =T40 -> 0.0208 | V40: =U40 -> 0.0208 | ... Z40: =Y40 -> 0.0208
B41: =B8 -> MATIERE | C41: 0.004 | D41: 0.004 | E41: 0.004 | F41: 0.004 | G41: 0.004 | H41: 0.004 | I41: 0.004 | J41: 0.004 | K41: 0.004 | L41: 0.004 | M41: 0.004 | N41: 0.004 | O41: =N41 -> 0.004 | P41: =O41 -> 0.004 | Q41: =P41 -> 0.004 | R41: =Q41 -> 0.004 | S41: =R41 -> 0.004 | T41: =S41 -> 0.004 | U41: =T41 -> 0.004 | V41: =U41 -> 0.004 | ... Z41: =Y41 -> 0.004
B42: =B9 -> ATTENTE AMONT | C42: 0.003 | D42: 0.003 | E42: 0.003 | F42: 0.003 | G42: 0.003 | H42: 0.003 | I42: 0.003 | J42: 0.003 | K42: 0.003 | L42: 0.003 | M42: 0.003 | N42: 0.003 | O42: =N42 -> 0.003 | P42: =O42 -> 0.003 | Q42: =P42 -> 0.003 | R42: =Q42 -> 0.003 | S42: =R42 -> 0.003 | T42: =S42 -> 0.003 | U42: =T42 -> 0.003 | V42: =U42 -> 0.003 | ... Z42: =Y42 -> 0.003
B43: =B10 -> SATURATION | C43: 0.001 | D43: 0.001 | E43: 0.001 | F43: 0.001 | G43: 0.001 | H43: 0.001 | I43: 0.001 | J43: 0.001 | K43: 0.001 | L43: 0.001 | M43: 0.001 | N43: 0.001 | O43: =N43 -> 0.001 | P43: =O43 -> 0.001 | Q43: =P43 -> 0.001 | R43: =Q43 -> 0.001 | S43: =R43 -> 0.001 | T43: =S43 -> 0.001 | U43: =T43 -> 0.001 | V43: =U43 -> 0.001 | ... Z43: =Y43 -> 0.001
B44: =B11 -> PREPARATION CONVOI | C44: 0.001 | D44: 0.001 | E44: 0.001 | F44: 0.001 | G44: 0.001 | H44: 0.001 | I44: 0.001 | J44: 0.001 | K44: 0.001 | L44: 0.001 | M44: 0.001 | N44: 0.001 | O44: =N44 -> 0.001 | P44: =O44 -> 0.001 | Q44: =P44 -> 0.001 | R44: =Q44 -> 0.001 | S44: =R44 -> 0.001 | T44: =S44 -> 0.001 | U44: =T44 -> 0.001 | V44: =U44 -> 0.001 | ... Z44: =Y44 -> 0.001
B45: =B12 -> OPERATEURS | C45: 0.001 | D45: 0.001 | E45: 0.001 | F45: 0.001 | G45: 0.001 | H45: 0.001 | I45: 0.001 | J45: 0.001 | K45: 0.001 | L45: 0.001 | M45: 0.001 | N45: 0.001 | O45: =N45 -> 0.001 | P45: =O45 -> 0.001 | Q45: =P45 -> 0.001 | R45: =Q45 -> 0.001 | S45: =R45 -> 0.001 | T45: =S45 -> 0.001 | U45: =T45 -> 0.001 | V45: =U45 -> 0.001 | ... Z45: =Y45 -> 0.001
B46: =B13 -> NON RENSEIGNEE | C46: 0.005 | D46: 0.005 | E46: 0.005 | F46: 0.005 | G46: 0.005 | H46: 0.005 | I46: 0.005 | J46: 0.005 | K46: 0.005 | L46: 0.005 | M46: 0.005 | N46: 0.005 | O46: =N46 -> 0.005 | P46: =O46 -> 0.005 | Q46: =P46 -> 0.005 | R46: =Q46 -> 0.005 | S46: =R46 -> 0.005 | T46: =S46 -> 0.005 | U46: =T46 -> 0.005 | V46: =U46 -> 0.005 | ... Z46: =Y46 -> 0.005
... B57: =B24 -> PERTES CYCLE | C57: 0.03 | D57: 0.03 | E57: 0.03 | F57: 0.03 | G57: 0.03 | H57: 0.03 | I57: 0.03 | J57: 0.03 | K57: 0.03 | L57: 0.03 | M57: 0.03 | N57: 0.03 | O57: =N57 -> 0.03 | P57: =O57 -> 0.03 | Q57: =P57 -> 0.03 | R57: =Q57 -> 0.03 | S57: =R57 -> 0.03 | T57: =S57 -> 0.03 | U57: =T57 -> 0.03 | V57: =U57 -> 0.03 | ... Z57: =Y57 -> 0.03
B58: NON RO GLOBAL | C58: 0.17001137 | D58: 0.17001137 | E58: 0.17001137 | F58: 0.17001137 | G58: 0.17001137 | H58: 0.17001137 | I58: 0.17001137 | J58: 0.17001137 | K58: 0.17001137 | L58: 0.17001137 | M58: 0.17001137 | N58: 0.17001137 | O58: =SUM(O35:O57) -> 0.2117 | P58: =SUM(P35:P57) -> 0.2117 | Q58: =SUM(Q35:Q57) -> 0.2117 | R58: =SUM(R35:R57) -> 0.2117 | S58: =SUM(S35:S57) -> 0.2117 | T58: =SUM(T35:T57) -> 0.2117 | U58: =SUM(U35:U57) -> 0.2117 | V58: =SUM(V35:V57) -> 0.2117 | ... Z58: =SUM(Z35:Z57) -> 0.2117
B59: =B26 -> ARRETS MACHINES | C59: 0.05 | D59: 0.05 | E59: 0.05 | F59: 0.05 | G59: 0.05 | H59: 0.05 | I59: 0.05 | J59: 0.05 | K59: 0.05 | L59: 0.05 | M59: 0.05 | N59: 0.05 | O59: =SUM(O35:O37) -> 0.063 | P59: =SUM(P35:P37) -> 0.063 | Q59: =SUM(Q35:Q37) -> 0.063 | R59: =SUM(R35:R37) -> 0.063 | S59: =SUM(S35:S37) -> 0.063 | T59: =SUM(T35:T37) -> 0.063 | U59: =SUM(U35:U37) -> 0.063 | V59: =SUM(V35:V37) -> 0.063 | ... Z59: =SUM(Z35:Z37) -> 0.063
B60: =B27 -> ARRETS OUTILS | C60: 0.0389 | D60: 0.0389 | E60: 0.0389 | F60: 0.0389 | G60: 0.0389 | H60: 0.0389 | I60: 0.0389 | J60: 0.0389 | K60: 0.0389 | L60: 0.0389 | M60: 0.0389 | N60: 0.0389 | O60: =SUM(O38:O40) -> 0.0378 | P60: =SUM(P38:P40) -> 0.0378 | Q60: =SUM(Q38:Q40) -> 0.0378 | R60: =SUM(R38:R40) -> 0.0378 | S60: =SUM(S38:S40) -> 0.0378 | T60: =SUM(T38:T40) -> 0.0378 | U60: =SUM(U38:U40) -> 0.0378 | V60: =SUM(V38:V40) -> 0.0378 | ... Z60: =SUM(Z38:Z40) -> 0.0378
B61: =B28 -> ARRETS INDUITS | C61: 0.0167 | D61: 0.0167 | E61: 0.0167 | F61: 0.0167 | G61: 0.0167 | H61: 0.0167 | I61: 0.0167 | J61: 0.0167 | K61: 0.0167 | L61: 0.0167 | M61: 0.0167 | N61: 0.0167 | O61: =SUM(O41:O46) -> 0.015 | P61: =SUM(P41:P46) -> 0.015 | Q61: =SUM(Q41:Q46) -> 0.015 | R61: =SUM(R41:R46) -> 0.015 | S61: =SUM(S41:S46) -> 0.015 | T61: =SUM(T41:T46) -> 0.015 | U61: =SUM(U41:U46) -> 0.015 | V61: =SUM(V41:V46) -> 0.015 | ... Z61: =SUM(Z41:Z46) -> 0.015
...

Sheet Paramétrage
A1: Par défaut le fichier prend la date du jour en cours en référence. Si vous souhaitez changer la date, remplir la case jaune : | G1: 44203
A4: Onglet de paramétrage général | B4: Les valeurs en bleu sont à remplir par les usines, le reste est fait en automatique
E5: Onglet * | F5: Nom usuel | G5: Position objectif | J5: RO
A6: Lieu archivage export SAPIA | B6: http://docinfogroupe.inetpsa.com/ead/doc/ref._PSA13_5154/v.vc/[pj] | D6: Ligne 1 | E6: R001 | F6: LIGNE 1 | G6: =INT(MATCH(E6,Objectifs!A:A,0)/$G$28)+1 -> 1 | I6: FAMILLES DE PERTES | J6: PRESSES | K6: x
A7: Nom du document | D7: Ligne 2 | E7: R825 | F7: TDM 825 | G7: =INT(MATCH(E7,Objectifs!A:A,0)/$G$28)+1 -> #N/A | J7: EQUIPEMENTS | K7: x
A8: Date virtuelle pour Excel : | B8: =IF('Paramétrage'!G1="",TODAY(),G1) -> 44203 | D8: Ligne 3 | E8: R801 | F8: PTD | G8: =INT(MATCH(E8,Objectifs!A:A,0)/$G$28)+1 -> #N/A | J8: CONVOYEURS | K8: x
A9: Centre | B9: DI/DCPS | D9: Ligne 4 | E9: R802 | F9: L802 | G9: =INT(MATCH(E9,Objectifs!A:A,0)/$G$28)+1 -> #N/A | J9: OUTILS | K9: x
A10: Reponsable des documents | B10: T. RANCON | D10: Ligne 5 | E10: D601 | F10: T601 | G10: =INT(MATCH(E10,Objectifs!A:A,0)/$G$28)+1 -> 3 | J10: ESSUYAGE OUTIL | K10: x
A11: Responsable Mise à jour | B11: F. PETREQUIN | D11: Ligne 6 | E11: R803 | F11: L803 | G11: =INT(MATCH(E11,Objectifs!A:A,0)/$G$28)+1 -> 2 | J11: MECANISATIONS | K11: x
A12: Concaténation | B12: =B6&B7 -> http://docinfogroupe.inetpsa.com/ead/doc/ref._PSA13_5154/v.vc/[pj] | D12: Ligne 7 | G12: =INT(MATCH(E12,Objectifs!A:A,0)/$G$28)+1 -> #N/A | J12: MATIERE | K12: x
A13: Bilan réalisé avec | B13: Vision gammes série uniquement | D13: Ligne 8 | G13: =INT(MATCH(E13,Objectifs!A:A,0)/$G$28)+1 -> #N/A | J13: ATTENTE AMONT
D14: Ligne 9 | G14: =INT(MATCH(E14,Objectifs!A:A,0)/$G$28)+1 -> #N/A | J14: SATURATION
D15: Ligne 10 | G15: =INT(MATCH(E15,Objectifs!A:A,0)/$G$28)+1 -> #N/A | J15: PREPARATION CONVOI | K15: x
A16: R806 | D16: Ligne 11 | G16: =INT(MATCH(E16,Objectifs!A:A,0)/$G$28)+1 -> #N/A | J16: OPERATEURS | K16: x
D17: Ligne 12 | G17: =INT(MATCH(E17,Objectifs!A:A,0)/$G$28)+1 -> #N/A | J17: NON RENSEIGNEE | K17: x
D18: Ligne 13 | G18: =INT(MATCH(E18,Objectifs!A:A,0)/$G$28)+1 -> #N/A | J18: MONTAGE CONVOI | K18: x
D19: Ligne 14 | G19: =INT(MATCH(E19,Objectifs!A:A,0)/$G$28)+1 -> #N/A | J19: REMPLISSAGE
D20: Ligne 15 | G20: =INT(MATCH(E20,Objectifs!A:A,0)/$G$28)+1 -> #N/A | J20: PRE-ACCEPTATION | K20: x
D21: * ce nom doit être celui de l'onglet de l'export excel SAPIA | J21: CHANGEMENT D'INDEX
J22: MISE EN OPERATION | K22: x
C23: Correspondance Maturité Gamme | J23: CHANGEMENT DE BOBINE | K23: x
C24: * | D24: Vision toutes gammes | J24: CHANGEMENT DE BAC | K24: x
C25: =TEXT(0,0) -> 0 | D25: Vision gammes en lancement uniquement | J25: CHANGEMENT DE PALETTE | K25: x
C26: =TEXT(1,0) -> 1 | D26: Vision gammes nouvelles sur site | J26: REBUTS
C27: =TEXT(2,0) -> 2 | D27: Vision gammes série uniquement | J27: RETOUCHES
G28: =MATCH("PRESSES",Objectifs!B10:B405,0)-MATCH("PRESSES",Objectifs!B:B,0)+9 -> 33 | J28: PERTES CYCLE
C29: Nb lignes d'écart entre 2 tableaux d'obj. | G29: =MATCH("PRESSES",Objectifs!B1:B396,0) -> 2 | I29: TYPE DE PERTES | J29: ARRETS MACHINES
G30: =-MATCH("PRESSES",Objectifs!B:B,0) -> -2 | J30: ARRETS OUTILS
J31: ARRETS INDUITS
J32: ARRETS FONCTIONNELS
J33: PERTES QUALITE
J34: PERTES CYCLE
